<mujoco model="iiwa_gripper">

    <!-- <compiler meshdir="assets" texturedir="asset"/> -->
    <compiler angle="radian" />
    <statistic extent="1.5" meansize=".05"/>

    <option timestep="0.001" jacobian="sparse"/>

    <keyframe>
        <key time="0" qpos="0 0 0 0 0 0 0  0 0 0 0 0 0" />
    </keyframe>

    

    <!-- Physical limits of the actuator. -->
    <!-- Values taken from kuka_lbr_iiwa_brochure_en.pdf (see website) -->
    

    <actuator>
        <motor ctrllimited="true" ctrlrange="-176.0 176.0" joint="joint_1" name="torq_j1"/>
        <motor ctrllimited="true" ctrlrange="-176.0 176.0" joint="joint_2" name="torq_j2"/>
        <motor ctrllimited="true" ctrlrange="-110.0 110.0" joint="joint_3" name="torq_j3"/>
        <motor ctrllimited="true" ctrlrange="-110.0 110.0" joint="joint_4" name="torq_j4"/>
        <motor ctrllimited="true" ctrlrange="-110.0 110.0" joint="joint_5" name="torq_j5"/>
        <motor ctrllimited="true" ctrlrange="-40.0 40.0" joint="joint_6" name="torq_j6"/>
        <motor ctrllimited="true" ctrlrange="-40.0 40.0" joint="joint_7" name="torq_j7"/>

        <position name='finger_1' ctrllimited="true" kp="20" joint='finger_joint' ctrlrange='0 0.8'/>
        <position name='finger_2' ctrllimited="true" kp="20" joint='right_outer_knuckle_joint' ctrlrange='0 0.8'/>
    </actuator>

    <tendon>
		<!--finger2 tendons-->
        <fixed name="finger2_12_cpl" range="-1 1" stiffness="0.4" springlength="0.001" limited="true">
			<joint joint="finger_joint"  coef="1"/>
			<joint joint="left_inner_finger_joint"  coef="-3"/>
			<joint joint="left_inner_knuckle_joint"  coef="1"/>
		</fixed>

		<!--Finger1 tendons-->
        <fixed name="finger1_12_cpl" range="-1 1" stiffness="0.4" springlength="0.001" limited="true">
			<joint joint="right_outer_knuckle_joint"  coef="1"/>
			<joint joint="right_inner_finger_joint"  coef="-3"/>
			<joint joint="right_inner_knuckle_joint"  coef="1"/>
		</fixed>
	</tendon>

    <asset>
        <mesh name="link_0" file="meshes/link_0.stl" />
        <mesh name="link_1" file="meshes/link_1.stl" />
        <mesh name="link_2" file="meshes/link_2.stl" />
        <mesh name="link_3" file="meshes/link_3.stl" />
        <mesh name="link_4" file="meshes/link_4.stl" />
        <mesh name="link_5" file="meshes/link_5.stl" />
        <mesh name="link_6" file="meshes/link_6.stl" />
        <mesh name="link_7" file="meshes/link_7.stl" />
        <mesh name="link_0_vis" file="meshes/link_0_vis.stl" />
        <mesh name="link_1_vis" file="meshes/link_1_vis.stl" />
        <mesh name="link_2_vis" file="meshes/link_2_vis.stl" />
        <mesh name="link_3_vis" file="meshes/link_3_vis.stl" />
        <mesh name="link_4_vis" file="meshes/link_4_vis.stl" />
        <mesh name="link_5_vis" file="meshes/link_5_vis.stl" />
        <mesh name="link_6_vis" file="meshes/link_6_vis.stl" />
        <mesh name="link_7_vis" file="meshes/link_7_vis.stl" />

        <mesh name="robotiq_arg2f_base_link" file="meshes/robotiq_85_gripper/robotiq_arg2f_base_link.stl" />
        <mesh name="robotiq_arg2f_85_outer_knuckle" file="meshes/robotiq_85_gripper/robotiq_arg2f_85_outer_knuckle.stl" scale="0.001 0.001 0.001" />
        <mesh name="robotiq_arg2f_85_outer_finger" file="meshes/robotiq_85_gripper/robotiq_arg2f_85_outer_finger.stl" scale="0.001 0.001 0.001" />
        <mesh name="robotiq_arg2f_85_inner_finger" file="meshes/robotiq_85_gripper/robotiq_arg2f_85_inner_finger.stl" scale="0.001 0.001 0.001" />
        <mesh name="robotiq_arg2f_85_inner_knuckle" file="meshes/robotiq_85_gripper/robotiq_arg2f_85_inner_knuckle.stl" scale="0.001 0.001 0.001" />
        <mesh name="robotiq_arg2f_base_link_vis" file="meshes/robotiq_85_gripper/robotiq_arg2f_85_base_link_vis.stl" />
        <mesh name="robotiq_arg2f_85_outer_knuckle_vis" file="meshes/robotiq_85_gripper/robotiq_arg2f_85_outer_knuckle_vis.stl" scale="0.001 0.001 0.001" />
        <mesh name="robotiq_arg2f_85_outer_finger_vis" file="meshes/robotiq_85_gripper/robotiq_arg2f_85_outer_finger_vis.stl" scale="0.001 0.001 0.001" />
        <mesh name="robotiq_arg2f_85_inner_finger_vis" file="meshes/robotiq_85_gripper/robotiq_arg2f_85_inner_finger_vis.stl" scale="0.001 0.001 0.001" />
        <mesh name="robotiq_arg2f_85_inner_knuckle_vis" file="meshes/robotiq_85_gripper/robotiq_arg2f_85_inner_knuckle_vis.stl" scale="0.001 0.001 0.001" />

         <texture type="skybox" builtin="gradient" rgb1="0.3 0.5 0.7" rgb2="0 0 0" width="512" height="512"/>

        <texture name="texplane" type="2d" builtin="checker" rgb1=".2 .3 .4" rgb2=".1 0.15 0.2"
      width="512" height="512" mark="cross" markrgb=".8 .8 .8"/>
      <material name="matplane" reflectance="0.3" texture="texplane" texrepeat="1 1" texuniform="true"/>
    </asset>
    <worldbody>

    <light directional="true" diffuse=".4 .4 .4" specular="0.1 0.1 0.1" pos="0 0 5.0" dir="0 0 -1" castshadow="false"/>
    <light directional="true" diffuse=".6 .6 .6" specular="0.2 0.2 0.2" pos="0 0 4" dir="0 0 -1"/>

    <geom name="ground" type="plane" size="0 0 1" pos="0 0 0" quat="1 0 0 0" material="matplane" condim="1"/>

        <body name="base" pos="0 0 0">
            <!-- robot view -->
            <camera mode="fixed" name="robotview" pos="1.0 0 0.4" quat="0.653 0.271 0.271 0.653"/>
            <inertial diaginertia="0 0 0" mass="0" pos="0 0 0"/>
            <!-- mount attached here -->
            <geom type="mesh" pos="0 0 0" contype="0" conaffinity="0" group="1" rgba="0.4 0.4 0.4 1" name="link_0_visual" mesh="link_0_vis" />
            <geom type="mesh" pos="0 0 0" rgba="0.4 0.4 0.4 1" contype="0" mesh="link_0" name="link_0_collision" />
            <body name="link_1" pos="0 0 0.15">
                <inertial pos="0 -0.03 0.12" quat="0.428904 0.562175 -0.562175 0.428904" mass="3.4525" diaginertia="0.0218946 0.02183 0.00663837" />
                <joint name="joint_1" pos="0 0 0" axis="0 0 1" limited="true" range="-2.96706 2.96706" damping="0.1" />
                <geom pos="0 0 0.0075" type="mesh" contype="0" conaffinity="0" group="1" rgba="0.4 0.4 0.4 1" name="link_1_visual" mesh="link_1_vis" />
                <geom pos="0 0 0.0075" type="mesh" contype="0" rgba="0.4 0.4 0.4 1" mesh="link_1" name="link_1_collision" />
                <body name="link_2" pos="0 0 0.19" quat="0 0 0.707107 0.707107">
                    <inertial pos="0.0003 0.059 0.042" quat="0.701371 0.0898824 0.0898824 0.701371" mass="3.4821" diaginertia="0.02179 0.0217049 0.00684512" />
                    <joint name="joint_2" pos="0 0 0" axis="0 0 1" limited="true" range="-2.0944 2.0944" damping="0.1" />
                    <geom type="mesh" contype="0" conaffinity="0" group="1" rgba="1 0.423529 0.0392157 1" name="link_2_visual" mesh="link_2_vis" />
                    <geom type="mesh" contype="0" rgba="1 0.423529 0.0392157 1" mesh="link_2" name="link_2_collision" />
                    <body name="link_3" pos="0 0.21 0" quat="0 0 0.707107 0.707107">
                        <inertial pos="0 0.03 0.13" quat="0.56292 0.427927 -0.427927 0.56292" mass="4.05623" diaginertia="0.0321488 0.03204 0.00799117" />
                        <joint name="joint_3" pos="0 0 0" axis="0 0 1" limited="true" range="-2.96706 2.96706" damping="0.1" />
                        <geom pos="0 0 -0.026" type="mesh" contype="0" conaffinity="0" group="1" rgba="0.4 0.4 0.4 1" name="link_3_visual" mesh="link_3_vis" />
                        <geom pos="0 0 -0.026" type="mesh" contype="0" rgba="0.4 0.4 0.4 1" mesh="link_3" name="link_3_collision" />
                        <body name="link_4" pos="0 0 0.19" quat="0.707107 0.707107 0 0">
                            <inertial pos="0 0.067 0.034" quat="0.991887 -0.127124 0 0" mass="3.4822" diaginertia="0.02178 0.0216947 0.00684029" />
                            <joint name="joint_4" pos="0 0 0" axis="0 0 1" limited="true" range="-2.0944 2.0944" damping="0.1" />
                            <geom type="mesh" contype="0" conaffinity="0" group="1" rgba="1 0.423529 0.0392157 1" name="link_4_visual" mesh="link_4_vis" />
                            <geom type="mesh" contype="0" rgba="1 0.423529 0.0392157 1" mesh="link_4" name="link_4_collision" />
                            <body name="link_5" pos="0 0.21 0" quat="0 0 0.707107 0.707107">
                                <inertial pos="0.0001 0.021 0.076" quat="0.365352 0.605407 -0.605407 0.365352" mass="2.1633" diaginertia="0.0131987 0.01287 0.0036293" />
                                <joint name="joint_5" pos="0 0 0" axis="0 0 1" limited="true" range="-2.96706 2.96706" damping="0.1" />
                                <geom pos="0 0 -0.026" type="mesh" contype="0" conaffinity="0" group="1" rgba="0.4 0.4 0.4 1" name="link_5_visual" mesh="link_5_vis" />
                                <geom pos="0 0 -0.026" type="mesh" contype="0" rgba="0.4 0.4 0.4 1" mesh="link_5" name="link_5_collision" />
                                <body name="link_6" pos="0 0.0607 0.19" quat="0.707107 0.707107 0 0">
                                    <inertial pos="0 0.0006 0.0004" quat="0.996112 0.088097 0 0" mass="2.3466" diaginertia="0.006509 0.00631585 0.00447015" />
                                    <joint name="joint_6" pos="0 0 0" axis="0 0 1" limited="true" range="-2.0944 2.0944" damping="0.1" />
                                    <geom type="mesh" contype="0" conaffinity="0" group="1" mesh="link_6_vis" name="link_6_visual" rgba="1 0.423529 0.0392157 1" />
                                    <geom type="mesh" contype="0" rgba="1 0.423529 0.0392157 1" mesh="link_6" name="link_6_collision" />
                                    <body name="link_7" pos="0 0.081 0.0607" quat="0 0 0.707107 0.707107">
                                        <inertial pos="0 0 0.02" quat="0.923068 0 0 0.384636" mass="3.129" diaginertia="0.0152362 0.0140538 0.002872" />
                                        <joint name="joint_7" pos="0 0 0" axis="0 0 1" limited="true" range="-3.05433 3.05433" damping="0.1" />
                                        <geom pos="0 0 -0.0005" type="mesh" contype="0" conaffinity="0" group="1" rgba="0.4 0.4 0.4 1" mesh="link_7_vis" name="link_7_visual" />
                                        <geom pos="0 0 -0.0005" type="mesh" contype="0" rgba="0.4 0.4 0.4 1" mesh="link_7" name="link_7_collision" />
                                        <body name="right_hand" pos="0 0 0.044" quat="0 0 0 1">
                                            <!-- This camera points out from the eef. -->
                                            <camera mode="fixed" name="eye_in_hand" pos="0.05 0 0" quat="0 0.707108 0.707108 0" fovy="75"/>
                                            <!-- To add gripper -->
                                            <body name="robotiq_85_adapter_link" pos="0.0 0 0" >
                                                <site name="ft_frame" pos="0 0 0" size="0.01 0.01 0.01" rgba="1 0 0 1" type="sphere" group="1" />
                                                <!-- This site was added for visualization. -->
                                                <body name="eef" pos="0 0 0.145" quat="0.707105 0 0 -0.707105">
                                                    <site name="grip_site" pos="0 0 0" size="0.01 0.01 0.01" rgba="1 0 0 0.5" type="sphere" group="1"/>
                                                    <site name="ee_x" pos="0.1 0 0" size="0.005 .1"  quat="0.707105  0 0.707108 0 " rgba="1 0 0 0" type="cylinder" group="1"/>
                                                    <site name="ee_y" pos="0 0.1 0" size="0.005 .1" quat="0.707105 0.707108 0 0" rgba="0 1 0 0" type="cylinder" group="1"/>
                                                    <site name="ee_z" pos="0 0 0.1" size="0.005 .1" quat="1 0 0 0" rgba="0 0 1 0" type="cylinder" group="1"/>
                                                    <!-- This site was added for visualization. -->
                                                    <site name="grip_site_cylinder" pos="0 0 0" size="0.005 10" rgba="0 1 0 0.3" type="cylinder" group="1"/>
                                                </body>
                                                <inertial pos="0 0 0" mass="0.01" diaginertia="0.001 0.001 0.001" />
                                                <geom type="mesh" contype="0" conaffinity="0" group="1" rgba="0.1 0.1 0.1 1" name="hand_visual" mesh="robotiq_arg2f_base_link" />
                                                <geom type="mesh" group="0" rgba="0.1 0.1 0.1 1" mesh="robotiq_arg2f_base_link" name="hand_collision" />
                                                <body name="left_outer_knuckle" pos="0 -0.0306011 0.054904" quat="0 0 0 1">
                                                    <inertial pos="0.000163875 0.0554825 -0.0100755" quat="0.920541 0.390623 -0.00362953 0.00231744" mass="0.0311462" diaginertia="5.11372e-05 4.89464e-05 4.95906e-06" />
                                                    <joint name="finger_joint" pos="0 0 0" axis="1 0 0" limited="true" range="0 0.8" />
                                                    <geom type="mesh" contype="0" conaffinity="0" group="1" rgba="0.792157 0.819608 0.933333 1" name="left_outer_knuckle_visual" mesh="robotiq_arg2f_85_outer_knuckle_vis" />
                                                    <geom type="mesh" group="0" rgba="0.792157 0.819608 0.933333 1" mesh="robotiq_arg2f_85_outer_knuckle" name="left_outer_knuckle_collision" solref="0.01 0.25" />
                                                    <geom pos="0 0.0315 -0.0041" type="mesh" contype="0" conaffinity="0" group="1" rgba="0.1 0.1 0.1 1" name="left_outer_finger_visual" mesh="robotiq_arg2f_85_outer_finger_vis" />
                                                    <geom pos="0 0.0315 -0.0041" type="mesh" group="0" rgba="0.1 0.1 0.1 1" mesh="robotiq_arg2f_85_outer_finger" name="left_outer_finger_collision" solref="0.01 0.25" />
                                                    <body name="left_inner_finger" pos="0 0.0376 0.043">
                                                        <inertial pos="0.000199506 0.0032692 0.00175282" quat="0.933621 0.35825 -0.00273441 0.00104851" mass="0.0156391" diaginertia="1.57977e-05 1.51089e-05 1.4647e-06" />
                                                        <joint name="left_inner_finger_joint" pos="0 0 0" axis="1 0 0" limited="true" range="-0.8757 0.8757" />
                                                        <geom type="mesh" contype="0" conaffinity="0" group="1" rgba="0.1 0.1 0.1 1" name="left_inner_finger_visual" mesh="robotiq_arg2f_85_inner_finger_vis" />
                                                        <geom type="mesh" group="0" rgba="0.1 0.1 0.1 1" mesh="robotiq_arg2f_85_inner_finger" name="left_inner_finger_collision" solref="0.01 0.25" />
                                                        <geom size="0.011 0.003175 0.01875" pos="0 -0.0220203 0.03242" type="box" contype="0" conaffinity="0" group="1" rgba="0.9 0.9 0.9 1" name="left_fingertip_visual" />
                                                        <geom size="0.011 0.003175 0.01875" pos="0 -0.0220203 0.03242" type="box" group="0" rgba="0.9 0.9 0.9 1" name="left_fingertip_collision" solref="0.01 0.25" />
                                                        <geom size="0.010 0.001 0.01675" pos="0 -0.0245203 0.03242" type="box" group="0" name="left_fingerpad_collision" />
                                                    </body>
                                                </body>
                                                <body name="left_inner_knuckle" pos="0 -0.0127 0.06142" quat="0 0 0 1">
                                                    <inertial pos="0.000123012 0.0507851 0.00103969" quat="0.497203 0.502496 -0.507943 0.492221" mass="0.0271177" diaginertia="2.83809e-05 2.61936e-05 2.81319e-06" />
                                                    <joint name="left_inner_knuckle_joint" pos="0 0 0" axis="1 0 0" limited="true" range="0 0.8757" />
                                                    <geom type="mesh" contype="0" conaffinity="0" group="1" rgba="0.1 0.1 0.1 1" name="left_inner_knuckle_visual" mesh="robotiq_arg2f_85_inner_knuckle_vis" />
                                                    <geom type="mesh" group="0" rgba="0.1 0.1 0.1 1" mesh="robotiq_arg2f_85_inner_knuckle" name="left_inner_knuckle_collision" />
                                                </body>
                                                <body name="right_outer_knuckle" pos="0 0.0306011 0.054904">
                                                    <inertial pos="0.000163875 0.0554825 -0.0100755" quat="0.920541 0.390623 -0.00362953 0.00231744" mass="0.0311462" diaginertia="5.11372e-05 4.89464e-05 4.95906e-06" />
                                                    <joint name="right_outer_knuckle_joint" pos="0 0 0" axis="1 0 0" limited="true" range="0 0.8" />
                                                    <geom type="mesh" contype="0" conaffinity="0" group="1" rgba="0.792157 0.819608 0.933333 1" name="right_outer_knuckle_visual" mesh="robotiq_arg2f_85_outer_knuckle_vis" />
                                                    <geom type="mesh" group="0" rgba="0.792157 0.819608 0.933333 1" mesh="robotiq_arg2f_85_outer_knuckle" name="right_outer_knuckle_collision" solref="0.01 0.25" />
                                                    <geom pos="0 0.0315 -0.0041" type="mesh" contype="0" conaffinity="0" group="1" rgba="0.1 0.1 0.1 1" name="right_outer_finger_visual" mesh="robotiq_arg2f_85_outer_finger_vis" />
                                                    <geom pos="0 0.0315 -0.0041" type="mesh" group="0" rgba="0.1 0.1 0.1 1" mesh="robotiq_arg2f_85_outer_finger" name="right_outer_finger_collision" solref="0.01 0.25" />
                                                    <body name="right_inner_finger" pos="0 0.0376 0.043">
                                                        <inertial pos="0.000199506 0.0032692 0.00175282" quat="0.933621 0.35825 -0.00273441 0.00104851" mass="0.0156391" diaginertia="1.57977e-05 1.51089e-05 1.4647e-06" />
                                                        <joint name="right_inner_finger_joint" pos="0 0 0" axis="1 0 0" limited="true" range="-0.8757 0.8757" />
                                                        <geom type="mesh" contype="0" conaffinity="0" group="1" rgba="0.1 0.1 0.1 1" name="right_inner_finger_visual" mesh="robotiq_arg2f_85_inner_finger_vis" />
                                                        <geom type="mesh" group="0" rgba="0.1 0.1 0.1 1" mesh="robotiq_arg2f_85_inner_finger" name="right_inner_finger_collision" solref="0.01 0.25" />
                                                        <geom size="0.011 0.003175 0.01875" pos="0 -0.0220203 0.03242" type="box" contype="0" conaffinity="0" group="1" rgba="0.9 0.9 0.9 1" name="right_fingertip_visual" />
                                                        <geom size="0.011 0.003175 0.01875" pos="0 -0.0220203 0.03242" type="box" group="0" rgba="0.9 0.9 0.9 1" name="right_fingertip_collision" solref="0.01 0.25" />
                                                        <geom size="0.010 0.001 0.01675" pos="0 -0.0245203 0.03242" type="box" group="0" name="right_fingerpad_collision" />
                                                    </body>
                                                </body>
                                                <body name="right_inner_knuckle" pos="0 0.0127 0.06142">
                                                    <inertial pos="0.000123012 0.0507851 0.00103969" quat="0.497203 0.502496 -0.507943 0.492221" mass="0.0271177" diaginertia="2.83809e-05 2.61936e-05 2.81319e-06" />
                                                    <joint name="right_inner_knuckle_joint" pos="0 0 0" axis="1 0 0" limited="true" range="0 0.8757" />
                                                    <geom type="mesh" contype="0" conaffinity="0" group="1" rgba="0.1 0.1 0.1 1" name="right_inner_knuckle_visual" mesh="robotiq_arg2f_85_inner_knuckle_vis" />
                                                    <geom type="mesh" group="0" rgba="0.1 0.1 0.1 1" mesh="robotiq_arg2f_85_inner_knuckle" name="right_inner_knuckle_collision" />
                                                </body>
                                            </body>
                                            
                                        </body>
                                    </body>
                                </body>
                            </body>
                        </body>
                    </body>
                </body>
            </body>
        </body>
    </worldbody>
    <sensor>
        <force name="force_ee" site="ft_frame"/>
        <torque name="torque_ee" site="ft_frame"/>
    </sensor>

</mujoco>
